<?xml version="1.0" ?>
<!-- =================================================================================== -->
<!-- |    This document was autogenerated by xacro from indomptable.urdf.xacro         | -->
<!-- |    EDITING THIS FILE BY HAND IS NOT RECOMMENDED                                 | -->
<!-- =================================================================================== -->
<!-- XML namespaces -->
<robot name="indomptable" xmlns:controller="http://playerstage.sourceforge.net/gazebo/xmlschema/#controller" xmlns:interface="http://playerstage.sourceforge.net/gazebo/xmlschema/#interface" xmlns:sensor="http://playerstage.sourceforge.net/gazebo/xmlschema/#sensor" xmlns:xacro="http://ros.org/wiki/xacro">
  <!--
	<include filename="$(find pi_robot_description)/urdf/sensors/hokuyo_laser_gazebo.xacro" />
	-->
  <!-- ============================   Body   ============================ -->
  <!--
 	<link name="world" />
 	-->
  <link name="base_link">
    <visual>
      <origin rpy="0 0 0" xyz="0 0 0"/>
      <geometry>
        <box size="0.27 0.31 0.003"/>
      </geometry>
      <material name="grey2">
        <color rgba="0.6 0.6 0.6 1.0"/>
      </material>
    </visual>
    <collision>
      <origin rpy="0 0 0" xyz="0 0 0"/>
      <geometry>
        <box size="0.27 0.31 0.003"/>
      </geometry>
    </collision>
    <inertial>
      <mass value="0.5"/>
      <inertia ixx="0.001" ixy="0.0" ixz="0.0" iyy="0.001" iyz="0.0" izz="0.001"/>
    </inertial>
  </link>
  <gazebo reference="base_link">
    <material>Gazebo/Grey</material>
    <selfCollide>false</selfCollide>
    <turnGravityOff>true</turnGravityOff>
  </gazebo>
  <link name="base_laser_bottom">
    <visual>
      <origin rpy="0 0 0" xyz="0 0 0"/>
      <geometry>
        <box size="0.05 0.05 0.041"/>
      </geometry>
      <material name="black1">
        <color rgba="0.2 0.2 0.2 1.0"/>
      </material>
    </visual>
    <collision>
      <origin rpy="0 0 0" xyz="0 0 0"/>
      <geometry>
        <box size="0.05 0.05 0.041"/>
      </geometry>
    </collision>
    <inertial>
      <mass value="0.1"/>
      <inertia ixx="0.001" ixy="0.0" ixz="0.0" iyy="0.001" iyz="0.0" izz="0.001"/>
    </inertial>
  </link>
  <gazebo reference="base_laser_bottom">
    <material>Gazebo/FlatBlack</material>
    <selfCollide>false</selfCollide>
    <turnGravityOff>true</turnGravityOff>
  </gazebo>
  <link name="base_laser">
    <visual>
      <origin rpy="0 0 0" xyz="0 0 0"/>
      <geometry>
        <cylinder length="0.029" radius="0.025"/>
      </geometry>
      <material name="black1">
        <color rgba="0.2 0.2 0.2 1.0"/>
      </material>
    </visual>
    <collision>
      <origin rpy="0 0 0" xyz="0 0 0"/>
      <geometry>
        <cylinder length="0.029" radius="0.025"/>
      </geometry>
    </collision>
    <inertial>
      <mass value="0.1"/>
      <inertia ixx="0.001" ixy="0.0" ixz="0.0" iyy="0.001" iyz="0.0" izz="0.001"/>
    </inertial>
  </link>
  <gazebo reference="base_laser">
    <material>Gazebo/Grey</material>
    <selfCollide>false</selfCollide>
    <turnGravityOff>true</turnGravityOff>
  </gazebo>
  <link name="netbook_level">
    <visual>
      <origin rpy="0 0 0" xyz="0 0 0"/>
      <geometry>
        <box size="0.27 0.31 0.003"/>
      </geometry>
      <material name="grey2">
        <color rgba="0.6 0.6 0.6 1.0"/>
      </material>
    </visual>
    <collision>
      <origin rpy="0 0 0" xyz="0 0 0"/>
      <geometry>
        <box size="0.27 0.31 0.003"/>
      </geometry>
    </collision>
    <inertial>
      <mass value="0.5"/>
      <inertia ixx="0.001" ixy="0.0" ixz="0.0" iyy="0.001" iyz="0.0" izz="0.001"/>
    </inertial>
  </link>
  <gazebo reference="netbook_level">
    <material>Gazebo/Grey</material>
    <selfCollide>false</selfCollide>
    <turnGravityOff>true</turnGravityOff>
  </gazebo>
  <link name="right_arm_panel">
    <visual>
      <origin rpy="0 0 0" xyz="0 0 0"/>
      <geometry>
        <box size="0.05 0.002 0.14"/>
      </geometry>
      <material name="grey2">
        <color rgba="0.6 0.6 0.6 1.0"/>
      </material>
    </visual>
    <collision>
      <origin rpy="0 0 0" xyz="0 0 0"/>
      <geometry>
        <box size="0.05 0.002 0.14"/>
      </geometry>
    </collision>
    <inertial>
      <mass value="0.5"/>
      <inertia ixx="0.001" ixy="0.0" ixz="0.0" iyy="0.001" iyz="0.0" izz="0.001"/>
    </inertial>
  </link>
  <gazebo reference="right_arm_panel">
    <material>Gazebo/Grey</material>
    <selfCollide>false</selfCollide>
    <turnGravityOff>true</turnGravityOff>
  </gazebo>
  <link name="left_arm_panel">
    <visual>
      <origin rpy="0 0 0" xyz="0 0 0"/>
      <geometry>
        <box size="0.05 0.002 0.14"/>
      </geometry>
      <material name="grey2">
        <color rgba="0.6 0.6 0.6 1.0"/>
      </material>
    </visual>
    <collision>
      <origin rpy="0 0 0" xyz="0 0 0"/>
      <geometry>
        <box size="0.05 0.002 0.14"/>
      </geometry>
    </collision>
    <inertial>
      <mass value="0.5"/>
      <inertia ixx="0.001" ixy="0.0" ixz="0.0" iyy="0.001" iyz="0.0" izz="0.001"/>
    </inertial>
  </link>
  <gazebo reference="left_arm_panel">
    <material>Gazebo/Grey</material>
    <selfCollide>false</selfCollide>
    <turnGravityOff>true</turnGravityOff>
  </gazebo>
  <link name="back_arm_panel">
    <visual>
      <origin rpy="0 0 0" xyz="0 0 0"/>
      <geometry>
        <box size="0.002 0.136 0.14"/>
      </geometry>
      <material name="grey2">
        <color rgba="0.6 0.6 0.6 1.0"/>
      </material>
    </visual>
    <collision>
      <origin rpy="0 0 0" xyz="0 0 0"/>
      <geometry>
        <box size="0.002 0.136 0.14"/>
      </geometry>
    </collision>
    <inertial>
      <mass value="0.5"/>
      <inertia ixx="0.001" ixy="0.0" ixz="0.0" iyy="0.001" iyz="0.0" izz="0.001"/>
    </inertial>
  </link>
  <gazebo reference="back_arm_panel">
    <material>Gazebo/Grey</material>
    <selfCollide>false</selfCollide>
    <turnGravityOff>true</turnGravityOff>
  </gazebo>
  <link name="right_panel">
    <visual>
      <origin rpy="0 0 0" xyz="0 0 0"/>
      <geometry>
        <box size="0.155 0.002 0.34"/>
      </geometry>
      <material name="grey2">
        <color rgba="0.6 0.6 0.6 1.0"/>
      </material>
    </visual>
    <collision>
      <origin rpy="0 0 0" xyz="0 0 0"/>
      <geometry>
        <box size="0.155 0.002 0.34"/>
      </geometry>
    </collision>
    <inertial>
      <mass value="0.5"/>
      <inertia ixx="0.001" ixy="0.0" ixz="0.0" iyy="0.001" iyz="0.0" izz="0.001"/>
    </inertial>
  </link>
  <gazebo reference="right_panel">
    <material>Gazebo/Grey</material>
    <selfCollide>false</selfCollide>
    <turnGravityOff>true</turnGravityOff>
  </gazebo>
  <link name="left_panel">
    <visual>
      <origin rpy="0 0 0" xyz="0 0 0"/>
      <geometry>
        <box size="0.155 0.002 0.34"/>
      </geometry>
      <material name="grey2">
        <color rgba="0.6 0.6 0.6 1.0"/>
      </material>
    </visual>
    <collision>
      <origin rpy="0 0 0" xyz="0 0 0"/>
      <geometry>
        <box size="0.155 0.002 0.34"/>
      </geometry>
    </collision>
    <inertial>
      <mass value="0.5"/>
      <inertia ixx="0.001" ixy="0.0" ixz="0.0" iyy="0.001" iyz="0.0" izz="0.001"/>
    </inertial>
  </link>
  <gazebo reference="left_panel">
    <material>Gazebo/Grey</material>
    <selfCollide>false</selfCollide>
    <turnGravityOff>true</turnGravityOff>
  </gazebo>
  <!-- ============================   Arms   ============================ -->
  <link name="left_shoulder_roll_link">
    <visual>
      <origin rpy="0 0 0" xyz="0 0 0"/>
      <geometry>
        <box size="0.05 0.03 0.03"/>
      </geometry>
      <material name="ax12_color">
        <color rgba="0.1 0.1 0.1 1.0"/>
      </material>
    </visual>
    <collision>
      <origin rpy="0 0 0" xyz="0 0 0"/>
      <geometry>
        <box size="0.05 0.03 0.03"/>
      </geometry>
    </collision>
    <inertial>
      <mass value="0.055"/>
      <inertia ixx="0.001" ixy="0.0" ixz="0.0" iyy="0.001" iyz="0.0" izz="0.001"/>
    </inertial>
  </link>
  <gazebo reference="left_shoulder_roll_link">
    <material>Gazebo/FlatBlack</material>
    <selfCollide>false</selfCollide>
    <turnGravityOff>true</turnGravityOff>
  </gazebo>
  <link name="left_shoulder_link">
    <visual>
      <origin rpy="0 0 0" xyz="0.007 0 0"/>
      <geometry>
        <box size="0.038 0.025 0.05"/>
      </geometry>
      <material name="bracket_color">
        <color rgba="0.9 0.9 0.9 1.0"/>
      </material>
    </visual>
    <collision>
      <origin rpy="0 0 0" xyz="0.007 0 0"/>
      <geometry>
        <box size="0.038 0.025 0.05"/>
      </geometry>
    </collision>
    <inertial>
      <mass value="0.05"/>
      <inertia ixx="0.001" ixy="0.0" ixz="0.0" iyy="0.001" iyz="0.0" izz="0.001"/>
    </inertial>
  </link>
  <gazebo reference="left_shoulder_link">
    <material>Gazebo/WhiteEmissive</material>
    <selfCollide>false</selfCollide>
    <turnGravityOff>true</turnGravityOff>
  </gazebo>
  <link name="left_shoulder_lift_link">
    <visual>
      <origin rpy="0 0 0" xyz="0 0 0"/>
      <geometry>
        <box size="0.05 0.03 0.03"/>
      </geometry>
      <material name="ax12_color">
        <color rgba="0.1 0.1 0.1 1.0"/>
      </material>
    </visual>
    <collision>
      <origin rpy="0 0 0" xyz="0 0 0"/>
      <geometry>
        <box size="0.05 0.03 0.03"/>
      </geometry>
    </collision>
    <inertial>
      <mass value="0.055"/>
      <inertia ixx="0.001" ixy="0.0" ixz="0.0" iyy="0.001" iyz="0.0" izz="0.001"/>
    </inertial>
  </link>
  <gazebo reference="left_shoulder_lift_link">
    <material>Gazebo/FlatBlack</material>
    <selfCollide>false</selfCollide>
    <turnGravityOff>true</turnGravityOff>
  </gazebo>
  <link name="left_shoulder_link2">
    <visual>
      <origin rpy="0 0 0" xyz="0.007 0 0"/>
      <geometry>
        <box size="0.038 0.05 0.025"/>
      </geometry>
      <material name="bracket_color">
        <color rgba="0.9 0.9 0.9 1.0"/>
      </material>
    </visual>
    <collision>
      <origin rpy="0 0 0" xyz="0.007 0 0"/>
      <geometry>
        <box size="0.038 0.05 0.025"/>
      </geometry>
    </collision>
    <inertial>
      <mass value="0.05"/>
      <inertia ixx="0.001" ixy="0.0" ixz="0.0" iyy="0.001" iyz="0.0" izz="0.001"/>
    </inertial>
  </link>
  <gazebo reference="left_shoulder_link2">
    <material>Gazebo/WhiteEmissive</material>
    <selfCollide>false</selfCollide>
    <turnGravityOff>true</turnGravityOff>
  </gazebo>
  <link name="left_elbow_servo_link">
    <visual>
      <origin rpy="0 0 0" xyz="0 0 0"/>
      <geometry>
        <box size="0.05 0.03 0.03"/>
      </geometry>
      <material name="ax12_color">
        <color rgba="0.1 0.1 0.1 1.0"/>
      </material>
    </visual>
    <collision>
      <origin rpy="0 0 0" xyz="0 0 0"/>
      <geometry>
        <box size="0.05 0.03 0.03"/>
      </geometry>
    </collision>
    <inertial>
      <mass value="0.055"/>
      <inertia ixx="0.001" ixy="0.0" ixz="0.0" iyy="0.001" iyz="0.0" izz="0.001"/>
    </inertial>
  </link>
  <gazebo reference="left_elbow_servo_link">
    <material>Gazebo/FlatBlack</material>
    <selfCollide>false</selfCollide>
    <turnGravityOff>true</turnGravityOff>
  </gazebo>
  <link name="left_elbow_link">
    <visual>
      <origin rpy="0 0 0" xyz="0.007 0 0"/>
      <geometry>
        <box size="0.038 0.05 0.025"/>
      </geometry>
      <material name="bracket_color">
        <color rgba="0.9 0.9 0.9 1.0"/>
      </material>
    </visual>
    <collision>
      <origin rpy="0 0 0" xyz="0.007 0 0"/>
      <geometry>
        <box size="0.038 0.05 0.025"/>
      </geometry>
    </collision>
    <inertial>
      <mass value="0.05"/>
      <inertia ixx="0.001" ixy="0.0" ixz="0.0" iyy="0.001" iyz="0.0" izz="0.001"/>
    </inertial>
  </link>
  <gazebo reference="left_elbow_link">
    <material>Gazebo/WhiteEmissive</material>
    <selfCollide>false</selfCollide>
    <turnGravityOff>true</turnGravityOff>
  </gazebo>
  <link name="left_wrist_lift_link">
    <visual>
      <origin rpy="0 0 0" xyz="0 0 0"/>
      <geometry>
        <box size="0.05 0.03 0.03"/>
      </geometry>
      <material name="ax12_color">
        <color rgba="0.1 0.1 0.1 1.0"/>
      </material>
    </visual>
    <collision>
      <origin rpy="0 0 0" xyz="0 0 0"/>
      <geometry>
        <box size="0.05 0.03 0.03"/>
      </geometry>
    </collision>
    <inertial>
      <mass value="0.055"/>
      <inertia ixx="0.001" ixy="0.0" ixz="0.0" iyy="0.001" iyz="0.0" izz="0.001"/>
    </inertial>
  </link>
  <gazebo reference="left_wrist_lift_link">
    <material>Gazebo/FlatBlack</material>
    <selfCollide>false</selfCollide>
    <turnGravityOff>true</turnGravityOff>
  </gazebo>
  <link name="left_wrist_link">
    <visual>
      <origin rpy="0 0 0" xyz="0.007 0 0"/>
      <geometry>
        <box size="0.038 0.05 0.025"/>
      </geometry>
      <material name="bracket_color">
        <color rgba="0.9 0.9 0.9 1.0"/>
      </material>
    </visual>
    <collision>
      <origin rpy="0 0 0" xyz="0.007 0 0"/>
      <geometry>
        <box size="0.038 0.05 0.025"/>
      </geometry>
    </collision>
    <inertial>
      <mass value="0.05"/>
      <inertia ixx="0.001" ixy="0.0" ixz="0.0" iyy="0.001" iyz="0.0" izz="0.001"/>
    </inertial>
  </link>
  <gazebo reference="left_wrist_link">
    <material>Gazebo/WhiteEmissive</material>
    <selfCollide>false</selfCollide>
    <turnGravityOff>true</turnGravityOff>
  </gazebo>
  <!--
	<xacro:arm side="right" reflect="-1" />
	-->
  <!-- =================== Joint Definitions ==================== -->
  <!--
	<joint name="base_world_link" type="continuous">
    	<parent link="world"/>
    	<child link="base_link"/>
    	<axis xyz="0 0 0"/>
    	<origin rpy="0 0 0" xyz="0 0 0"/>
    	<dynamics damping="0.05"/>
  	</joint>
  	-->
  <joint name="netbook_level_joint" type="fixed">
    <parent link="base_link"/>
    <child link="netbook_level"/>
    <origin rpy="0 0 0" xyz="0 0 0.253"/>
  </joint>
  <joint name="base_laser_bottom_joint" type="fixed">
    <parent link="base_link"/>
    <child link="base_laser_bottom"/>
    <origin rpy="0 0 0" xyz="0.11 0 0.022"/>
  </joint>
  <joint name="base_laser_joint" type="fixed">
    <parent link="base_laser_bottom"/>
    <child link="base_laser"/>
    <origin rpy="0 0 0" xyz="0 0 0.035"/>
  </joint>
  <joint name="left_arm_panel_joint" type="fixed">
    <parent link="base_link"/>
    <child link="left_arm_panel"/>
    <origin rpy="0 0 0" xyz="0.075 0.068 0.0715"/>
  </joint>
  <joint name="right_arm_panel_joint" type="fixed">
    <parent link="base_link"/>
    <child link="right_arm_panel"/>
    <origin rpy="0 0 0" xyz="0.075 -0.068 0.0715"/>
  </joint>
  <joint name="back_arm_panel_joint" type="fixed">
    <parent link="base_link"/>
    <child link="back_arm_panel"/>
    <origin rpy="0 0 0" xyz="0.05 0 0.0715"/>
  </joint>
  <joint name="left_panel_joint" type="fixed">
    <parent link="base_link"/>
    <child link="left_panel"/>
    <origin rpy="0 0 0" xyz="0 0.155 0.17"/>
  </joint>
  <joint name="right_panel_joint" type="fixed">
    <parent link="base_link"/>
    <child link="right_panel"/>
    <origin rpy="0 0 0" xyz="0 -0.155 0.17"/>
  </joint>
  <joint name="left_shoulder_joint" type="fixed">
    <parent link="left_arm_panel"/>
    <child link="left_shoulder_roll_link"/>
    <origin rpy="0 0 0" xyz="0 0.016 0.06"/>
    <axis xyz="1 0 0"/>
  </joint>
  <joint name="left_soulder_roll_joint" type="revolute">
    <parent link="left_shoulder_roll_link"/>
    <child link="left_shoulder_link"/>
    <origin rpy="0 0 0" xyz="0.01 0 0"/>
    <limit effort="10" lower="-2.53" upper="2.53" velocity="3"/>
    <axis xyz="0 0 1"/>
    <dynamics damping="0.0"/>
  </joint>
  <joint name="left_shoulder_joint2" type="fixed">
    <parent link="left_shoulder_link"/>
    <child link="left_shoulder_lift_link"/>
    <origin rpy="0 0 0" xyz="0.051 0 0"/>
    <axis xyz="1 0 0"/>
  </joint>
  <joint name="left_soulder_lift_joint" type="revolute">
    <parent link="left_shoulder_lift_link"/>
    <child link="left_shoulder_link2"/>
    <origin rpy="0 0 0" xyz="0.01 0 0"/>
    <limit effort="10" lower="-2.53" upper="2.53" velocity="3"/>
    <axis xyz="0 1 0"/>
    <dynamics damping="0.0"/>
  </joint>
  <joint name="left_elbow_servo_joint" type="fixed">
    <parent link="left_shoulder_link2"/>
    <child link="left_elbow_servo_link"/>
    <origin rpy="0 0 0" xyz="0.051 0 0"/>
    <axis xyz="0 1 0"/>
  </joint>
  <joint name="left_elbow_joint" type="revolute">
    <parent link="left_elbow_servo_link"/>
    <child link="left_elbow_link"/>
    <origin rpy="0 0 0" xyz="0.01 0 0"/>
    <limit effort="10" lower="-2.53" upper="2.53" velocity="3"/>
    <axis xyz="0 1 0"/>
    <dynamics damping="0.0"/>
  </joint>
  <joint name="left_wrist_lift_joint" type="fixed">
    <parent link="left_elbow_link"/>
    <child link="left_wrist_lift_link"/>
    <origin rpy="0 0 0" xyz="0.051 0 0"/>
    <axis xyz="0 1 0"/>
  </joint>
  <joint name="left_wrist_joint" type="revolute">
    <parent link="left_wrist_lift_link"/>
    <child link="left_wrist_link"/>
    <origin rpy="0 0 0" xyz="0.01 0 0"/>
    <limit effort="10" lower="-2.53" upper="2.53" velocity="3"/>
    <axis xyz="0 1 0"/>
    <dynamics damping="0.0"/>
  </joint>
  <!--        
 	<joint name="left_shoulder_joint" type="fixed">
    	<parent link="left_arm_panel" />
    	<child link="left_shoulder_link" />
    	<origin xyz="0 0.034 0.05" rpy="0 0 0" />
	</joint>
	
 	<joint name="left_shoulder_pan_joint" type="revolute">
    	<parent link="left_shoulder_link" />
    	<child link="left_shoulder_pan_link" />
    	<origin xyz="0 0.031 0" rpy="0 0 0" />
       	<limit lower="-2.53" upper="2.53" effort="10" velocity="3" />
        <axis xyz="0 0 1" />
    	<dynamics damping="0.0"/>
	</joint>
	
 	<joint name="left_shoulder_lift_joint" type="revolute">
    	<parent link="left_shoulder_pan_link" />
    	<child link="left_shoulder_lift_link" />
    	<origin xyz="0 0.047 0" rpy="0 -1.57 0" />
       	<limit lower="-2.53" upper="2.53" effort="10" velocity="3" />
        <axis xyz="0 1 0" />
    	<dynamics damping="0.0"/>
	</joint>
	
 	<joint name="left_upper_arm_bracket_joint" type="fixed">
    	<parent link="left_shoulder_lift_link" />
    	<child link="left_upper_arm_bracket_link" />
    	<origin xyz="0 0.009 -0.0465" rpy="0 0 0" />
	</joint>
	
 	<joint name="left_arm_roll_joint" type="revolute">
    	<parent link="left_upper_arm_bracket_link" />
    	<child link="left_arm_roll_link" />
        <limit lower="-2.53" upper="2.53" effort="10" velocity="3" />
    	<origin xyz="0 -0.009 -0.0175" rpy="0 0 0" />
        <axis xyz="0 0 -1" />
    	<dynamics damping="0.0"/>
	</joint>
	
 	<joint name="left_upper_elbow_bracket_joint" type="fixed">
    	<parent link="left_arm_roll_link" />
    	<child link="left_upper_elbow_bracket_link" />
    	<origin xyz="-0.012 0.009 -0.0175" rpy="0 0 -1.57" />
    	<dynamics damping="0.0"/>
	</joint>
	
 	<joint name="left_elbow_servo_joint" type="fixed">
    	<parent link="left_upper_elbow_bracket_link" />
    	<child link="left_elbow_servo_link" />
    	<origin xyz="0 0 -0.0275" rpy="0 0 1.57" />
        <axis xyz="0 1 0" />
	</joint>
	
 	<joint name="left_elbow_joint" type="revolute">
    	<parent link="left_elbow_servo_link" />
    	<child link="left_elbow_link" />
    	<origin xyz="0 0 0" rpy="0 0 0" />
        <limit lower="-2.53" upper="2.53" effort="10" velocity="3" />
        <axis xyz="1 0 0" />
    	<dynamics damping="0.0"/>
	</joint>
	
 	<joint name="left_wrist_bracket_joint" type="fixed">
    	<parent link="left_lower_arm_link" />
    	<child link="left_wrist_bracket_link" />
    	<origin xyz="0 0 -0.092" rpy="0 0 0" />
    	<dynamics damping="0.0"/>
	</joint>
	
 	<joint name="left_hand_joint" type="fixed">
    	<parent link="left_wrist_link" />
    	<child link="left_hand_link" />
    	<origin xyz="0 0 -0.041" rpy="0 0 0" />
	</joint>
	
 	<joint name="left_finger_joint" type="fixed">
    	<parent link="left_hand_link" />
    	<child link="left_finger_link" />
    	<origin xyz="0 0 -0.064" rpy="0 0 0" />
    	<dynamics damping="0.0"/>
	</joint>

        <joint name="left_lower_arm_joint" type="fixed">
        <parent link="left_elbow_link" />
        <child link="left_lower_arm_link" />
        <origin xyz="0 0 -0.038" rpy="0 0 0" />
        </joint>

        <joint name="left_wrist_joint" type="revolute">
        <parent link="left_wrist_bracket_link" />
        <child link="left_wrist_link" />
        <origin xyz="0 0 -0.026" rpy="0 0 0" />
        <limit lower="-2.53" upper="2.53" effort="10" velocity="3" />
        <axis xyz="1 0 0" />
        <dynamics damping="0.0"/>
        </joint>
-->
  <!--	
 	<joint name="right_shoulder_joint" type="fixed">
    	<parent link="right_arm_panel" />
    	<child link="right_shoulder_link" />
    	<origin xyz="0 -0.034 0.05" rpy="0 0 0" />
	</joint>

 	<joint name="right_shoulder_pan_joint" type="revolute">
    	<parent link="right_shoulder_link" />
    	<child link="right_shoulder_pan_link" />
    	<origin xyz="0 -0.031 0" rpy="0 0 0" />
       	<limit lower="-2.53" upper="2.53" effort="10" velocity="3" />
        <axis xyz="0 0 1" />
    	<dynamics damping="0.0"/>
	</joint>
	
 	<joint name="right_shoulder_lift_joint" type="revolute">
    	<parent link="right_shoulder_pan_link" />
    	<child link="right_shoulder_lift_link" />
    	<origin xyz="0 -0.047 0" rpy="0 -1.57 0" />
       	<limit lower="-2.53" upper="2.53" effort="10" velocity="3" />
        <axis xyz="0 -1 0" />
    	<dynamics damping="0.0"/>
	</joint>
	
 	<joint name="right_upper_arm_bracket_joint" type="fixed">
    	<parent link="right_shoulder_lift_link" />
    	<child link="right_upper_arm_bracket_link" />
    	<origin xyz="0 -0.009 -0.0465" rpy="0 0 0" />
	</joint>
	
 	<joint name="right_arm_roll_joint" type="revolute">
    	<parent link="right_upper_arm_bracket_link" />
    	<child link="right_arm_roll_link" />
        <limit lower="-2.53" upper="2.53" effort="10" velocity="3" />
    	<origin xyz="0 0.009 -0.0175" rpy="0 0 0" />
        <axis xyz="0 0 -1" />
    	<dynamics damping="0.0"/>
	</joint>
	
 	<joint name="right_upper_elbow_bracket_joint" type="fixed">
    	<parent link="right_arm_roll_link" />
    	<child link="right_upper_elbow_bracket_link" />
    	<origin xyz="-0.012 -0.009 -0.0175" rpy="0 0 -1.57" />
    	<dynamics damping="0.0"/>
	</joint>
	
 	<joint name="right_elbow_servo_joint" type="fixed">
    	<parent link="right_upper_elbow_bracket_link" />
    	<child link="right_elbow_servo_link" />
    	<origin xyz="0 0 -0.0275" rpy="0 0 1.57" />
        <axis xyz="0 -1 0" />
	</joint>
	
 	<joint name="right_elbow_joint" type="revolute">
    	<parent link="right_elbow_servo_link" />
    	<child link="right_elbow_link" />
    	<origin xyz="0 0 0" rpy="0 0 0" />
       	<limit lower="-2.53" upper="2.53" effort="10" velocity="3" />
        <axis xyz="1 0 0" />
    	<dynamics damping="0.0"/>
	</joint>
	
 	<joint name="right_lower_arm_joint" type="fixed">
    	<parent link="right_elbow_link" />
    	<child link="right_lower_arm_link" />
    	<origin xyz="0 0 -0.038" rpy="0 0 0" />
    	<dynamics damping="0.0"/>
	</joint>
	
 	<joint name="right_wrist_bracket_joint" type="fixed">
    	<parent link="right_lower_arm_link" />
    	<child link="right_wrist_bracket_link" />
    	<origin xyz="0 0 -0.092" rpy="0 0 0" />
	</joint>
	
 	<joint name="right_wrist_joint" type="revolute">
    	<parent link="right_wrist_bracket_link" />
    	<child link="right_wrist_link" />
    	<origin xyz="0 0 -0.026" rpy="0 0 0" />
       	<limit lower="-2.53" upper="2.53" effort="10" velocity="3" />
        <axis xyz="1 0 0" />
    	<dynamics damping="0.0"/>
	</joint>
	
 	<joint name="right_hand_joint" type="fixed">
    	<parent link="right_wrist_link" />
    	<child link="right_hand_link" />
    	<origin xyz="0 0 -0.041" rpy="0 0 0" />
	</joint>
	
 	<joint name="right_finger_joint" type="fixed">
    	<parent link="right_hand_link" />
    	<child link="right_finger_link" />
    	<origin xyz="0 0 -0.064" rpy="0 0 0" />
	</joint>
	-->
  <gazebo reference="indomptable">
  	</gazebo>
</robot>

